package academy.devdojo.maratonajava.javacore.Oexception.runtime.test;

public class RuntimeExceptionTest03 {
    public static void main(String[] args) {
        AbreConexao();
    }

    private static String AbreConexao() {
        try {
            System.out.println("Abrindo arquivo");
            System.out.println("Escrevendo dados no arquivo");
            return "Conexão aberta";
        } catch (Exception e) {
            e.printStackTrace();
        } finally {
            System.out.println("Fechando recurso liberado pelo SO");
        }
        return null;
    }//O bloco finally sempre será executado, independe se teve ou não uma exceção

    private static void AbreConexao2() {
        try {
            System.out.println("Abrindo arquivo");
            System.out.println("Escrevendo dados no arquivo");
            throw new RuntimeException();
        } finally {
            System.out.println("Fechando recurso liberado pelo SO");
        }
    }
}
